<?xml version="1.0"?>
<sdf version="1.9">
  <model name="ArduBiped_Proto">
    <pose>0 0 0.75 0 0 0</pose>
    <link name="torso">
      <inertial><mass>2.0</mass>
        <inertia><ixx>0.020</ixx><ixy>0</ixy><ixz>0</ixz><iyy>0.020</iyy><iyz>0</iyz><izz>0.010</izz></inertia>
      </inertial>
      <collision name="col"><geometry><box><size>0.15 0.10 0.25</size></box></geometry></collision>
      <visual name="vis"><geometry><box><size>0.15 0.10 0.25</size></box></geometry>
        <material><ambient>0.2 0.5 0.8 1</ambient><diffuse>0.2 0.5 0.8 1</diffuse></material>
      </visual>
      <sensor name="imu_sensor" type="imu"><always_on>1</always_on><update_rate>1000</update_rate></sensor>
    </link>
    <link name="head"><pose>0 0 0.175 0 0 0</pose>
      <inertial><mass>0.2</mass><inertia><ixx>0.0002</ixx><ixy>0</ixy><ixz>0</ixz><iyy>0.0002</iyy><iyz>0</iyz><izz>0.0002</izz></inertia></inertial>
      <collision name="col"><geometry><sphere><radius>0.05</radius></sphere></geometry></collision>
      <visual name="vis"><geometry><sphere><radius>0.05</radius></sphere></geometry>
        <material><ambient>0.9 0.75 0.6 1</ambient><diffuse>0.9 0.75 0.6 1</diffuse></material></visual>
    </link>
    <joint name="head_joint" type="fixed"><parent>torso</parent><child>head</child></joint>
    <link name="l_thigh"><pose>0 0.06 -0.125 0 0 0</pose>
      <inertial><mass>0.4</mass><inertia><ixx>0.003</ixx><ixy>0</ixy><ixz>0</ixz><iyy>0.003</iyy><iyz>0</iyz><izz>0.0001</izz></inertia></inertial>
      <collision name="col"><geometry><cylinder><radius>0.025</radius><length>0.20</length></cylinder></geometry></collision>
      <visual name="vis"><geometry><cylinder><radius>0.025</radius><length>0.20</length></cylinder></geometry>
        <material><ambient>0.2 0.5 0.8 1</ambient><diffuse>0.2 0.5 0.8 1</diffuse></material></visual>
    </link>
    <link name="l_shin"><pose>0 0.06 -0.325 0 0 0</pose>
      <inertial><mass>0.25</mass><inertia><ixx>0.001</ixx><ixy>0</ixy><ixz>0</ixz><iyy>0.001</iyy><iyz>0</iyz><izz>0.00008</izz></inertia></inertial>
      <collision name="col"><geometry><cylinder><radius>0.020</radius><length>0.20</length></cylinder></geometry></collision>
      <visual name="vis"><geometry><cylinder><radius>0.020</radius><length>0.20</length></cylinder></geometry>
        <material><ambient>0.3 0.6 0.9 1</ambient><diffuse>0.3 0.6 0.9 1</diffuse></material></visual>
    </link>
    <link name="l_foot"><pose>0 0.06 -0.440 0 0 0</pose>
      <inertial><mass>0.1</mass><inertia><ixx>0.0001</ixx><ixy>0</ixy><ixz>0</ixz><iyy>0.0001</iyy><iyz>0</iyz><izz>0.0001</izz></inertia></inertial>
      <collision name="col"><geometry><box><size>0.14 0.07 0.025</size></box></geometry></collision>
      <visual name="vis"><geometry><box><size>0.14 0.07 0.025</size></box></geometry>
        <material><ambient>0.1 0.1 0.1 1</ambient><diffuse>0.1 0.1 0.1 1</diffuse></material></visual>
    </link>
    <link name="r_thigh"><pose>0 -0.06 -0.125 0 0 0</pose>
      <inertial><mass>0.4</mass><inertia><ixx>0.003</ixx><ixy>0</ixy><ixz>0</ixz><iyy>0.003</iyy><iyz>0</iyz><izz>0.0001</izz></inertia></inertial>
      <collision name="col"><geometry><cylinder><radius>0.025</radius><length>0.20</length></cylinder></geometry></collision>
      <visual name="vis"><geometry><cylinder><radius>0.025</radius><length>0.20</length></cylinder></geometry>
        <material><ambient>0.2 0.5 0.8 1</ambient><diffuse>0.2 0.5 0.8 1</diffuse></material></visual>
    </link>
    <link name="r_shin"><pose>0 -0.06 -0.325 0 0 0</pose>
      <inertial><mass>0.25</mass><inertia><ixx>0.001</ixx><ixy>0</ixy><ixz>0</ixz><iyy>0.001</iyy><iyz>0</iyz><izz>0.00008</izz></inertia></inertial>
      <collision name="col"><geometry><cylinder><radius>0.020</radius><length>0.20</length></cylinder></geometry></collision>
      <visual name="vis"><geometry><cylinder><radius>0.020</radius><length>0.20</length></cylinder></geometry>
        <material><ambient>0.3 0.6 0.9 1</ambient><diffuse>0.3 0.6 0.9 1</diffuse></material></visual>
    </link>
    <link name="r_foot"><pose>0 -0.06 -0.440 0 0 0</pose>
      <inertial><mass>0.1</mass><inertia><ixx>0.0001</ixx><ixy>0</ixy><ixz>0</ixz><iyy>0.0001</iyy><iyz>0</iyz><izz>0.0001</izz></inertia></inertial>
      <collision name="col"><geometry><box><size>0.14 0.07 0.025</size></box></geometry></collision>
      <visual name="vis"><geometry><box><size>0.14 0.07 0.025</size></box></geometry>
        <material><ambient>0.1 0.1 0.1 1</ambient><diffuse>0.1 0.1 0.1 1</diffuse></material></visual>
    </link>
    <joint name="l_hip_pitch" type="revolute">
<<<<<<< Updated upstream
<<<<<<< Updated upstream
      <parent>torso</parent><child>l_hip_pitch_link</child>
      <axis>
        <xyz>0 1 0</xyz>
        <limit><lower>-1.571</lower><upper>0.523</upper><effort>200</effort><velocity>3</velocity></limit>
        <dynamics><damping>5.0</damping><friction>0.5</friction></dynamics>
      </axis>
    </joint>
    <joint name="l_knee" type="revolute">
      <parent>l_hip_pitch_link</parent><child>l_thigh</child>
      <axis>
        <xyz>0 1 0</xyz>
        <limit><lower>0</lower><upper>2.618</upper><effort>200</effort><velocity>3</velocity></limit>
        <dynamics><damping>5.0</damping><friction>0.5</friction></dynamics>
      </axis>
    </joint>
    <joint name="l_knee_shin" type="revolute">
      <parent>l_thigh</parent><child>l_shin</child>
      <axis>
        <xyz>0 1 0</xyz>
        <limit><lower>0</lower><upper>2.618</upper><effort>200</effort><velocity>3</velocity></limit>
        <dynamics><damping>5.0</damping><friction>0.5</friction></dynamics>
=======
      <parent>torso</parent><child>l_thigh</child>
      <pose>0 0.06 -0.025 0 0 0</pose>
      <axis><xyz>0 1 0</xyz>
        <limit><lower>-0.785</lower><upper>0.785</upper><effort>50</effort><velocity>5</velocity></limit>
        <dynamics><damping>8.0</damping><friction>1.0</friction></dynamics>
      </axis>
    </joint>
    <joint name="l_knee" type="revolute">
      <parent>l_thigh</parent><child>l_shin</child>
      <pose>0 0.06 -0.225 0 0 0</pose>
      <axis><xyz>0 1 0</xyz>
        <limit><lower>-0.1</lower><upper>1.571</upper><effort>50</effort><velocity>5</velocity></limit>
        <dynamics><damping>8.0</damping><friction>1.0</friction></dynamics>
>>>>>>> Stashed changes
      </axis>
    </joint>
    <joint name="l_ankle" type="fixed"><parent>l_shin</parent><child>l_foot</child></joint>
    <joint name="r_hip_pitch" type="revolute">
<<<<<<< Updated upstream
      <parent>torso</parent><child>r_hip_pitch_link</child>
      <axis>
        <xyz>0 1 0</xyz>
        <limit><lower>-1.571</lower><upper>0.523</upper><effort>200</effort><velocity>3</velocity></limit>
        <dynamics><damping>5.0</damping><friction>0.5</friction></dynamics>
      </axis>
    </joint>
    <joint name="r_knee" type="revolute">
      <parent>r_hip_pitch_link</parent><child>r_thigh</child>
      <axis>
        <xyz>0 1 0</xyz>
        <limit><lower>0</lower><upper>2.618</upper><effort>200</effort><velocity>3</velocity></limit>
        <dynamics><damping>5.0</damping><friction>0.5</friction></dynamics>
      </axis>
    </joint>
    <joint name="r_knee_shin" type="revolute">
      <parent>r_thigh</parent><child>r_shin</child>
      <axis>
        <xyz>0 1 0</xyz>
        <limit><lower>0</lower><upper>2.618</upper><effort>200</effort><velocity>3</velocity></limit>
        <dynamics><damping>5.0</damping><friction>0.5</friction></dynamics>
      </axis>
    </joint>
    <joint name="r_ankle" type="fixed">
      <parent>r_shin</parent><child>r_foot</child>
    </joint>
    <plugin name="ArduPilotPlugin" filename="ArduPilotPlugin">
      <fdm_addr>127.0.0.1</fdm_addr>
      <fdm_port_in>9002</fdm_port_in>
      <connectionTimeoutMaxCount>5</connectionTimeoutMaxCount>
      <lock_step>1</lock_step>
      <modelXYZToAirplaneXForwardZDown degrees="true">0 0 0 180 0 0</modelXYZToAirplaneXForwardZDown>
      <gazeboXYZToNED degrees="true">0 0 0 180 0 90</gazeboXYZToNED>
      <imuName>torso::imu_sensor</imuName>
      <control channel="0">
        <jointName>l_hip_pitch</jointName>
        <type>COMMAND</type>
        <cmd_topic>/l_hip_pitch/cmd</cmd_topic>
        <p_gain>5.0</p_gain>
        <servo_min>1000</servo_min><servo_max>2000</servo_max>
        <multiplier>1.571</multiplier><offset>-0.5</offset>
      </control>
      <control channel="1">
        <jointName>r_hip_pitch</jointName>
        <type>COMMAND</type>
        <cmd_topic>/r_hip_pitch/cmd</cmd_topic>
        <p_gain>5.0</p_gain>
        <servo_min>1000</servo_min><servo_max>2000</servo_max>
        <multiplier>1.571</multiplier><offset>-0.5</offset>
      </control>
      <control channel="2">
        <jointName>l_knee</jointName>
        <type>COMMAND</type>
        <cmd_topic>/l_knee/cmd</cmd_topic>
        <p_gain>5.0</p_gain>
        <servo_min>1000</servo_min><servo_max>2000</servo_max>
        <multiplier>2.618</multiplier><offset>-0.5</offset>
      </control>
      <control channel="3">
        <jointName>r_knee</jointName>
        <type>COMMAND</type>
        <cmd_topic>/r_knee/cmd</cmd_topic>
        <p_gain>5.0</p_gain>
        <servo_min>1000</servo_min><servo_max>2000</servo_max>
        <multiplier>2.618</multiplier><offset>-0.5</offset>
=======
      <parent>torso</parent><child>r_thigh</child>
      <pose>0 -0.06 -0.025 0 0 0</pose>
      <axis><xyz>0 1 0</xyz>
        <limit><lower>-0.785</lower><upper>0.785</upper><effort>50</effort><velocity>5</velocity></limit>
        <dynamics><damping>8.0</damping><friction>1.0</friction></dynamics>
      </axis>
    </joint>
    <joint name="r_knee" type="revolute">
      <parent>r_thigh</parent><child>r_shin</child>
      <pose>0 -0.06 -0.225 0 0 0</pose>
      <axis><xyz>0 1 0</xyz>
        <limit><lower>-0.1</lower><upper>1.571</upper><effort>50</effort><velocity>5</velocity></limit>
        <dynamics><damping>8.0</damping><friction>1.0</friction></dynamics>
      </axis>
    </joint>
    <joint name="r_ankle" type="fixed"><parent>r_shin</parent><child>r_foot</child></joint>
    <plugin filename="gz-sim-joint-position-controller-system" name="gz::sim::systems::JointPositionController">
      <joint_name>l_hip_pitch</joint_name><topic>/l_hip_pitch/cmd</topic>
      <p_gain>40</p_gain><i_gain>0.1</i_gain><d_gain>2.0</d_gain>
    </plugin>
    <plugin filename="gz-sim-joint-position-controller-system" name="gz::sim::systems::JointPositionController">
      <joint_name>r_hip_pitch</joint_name><topic>/r_hip_pitch/cmd</topic>
      <p_gain>40</p_gain><i_gain>0.1</i_gain><d_gain>2.0</d_gain>
    </plugin>
    <plugin filename="gz-sim-joint-position-controller-system" name="gz::sim::systems::JointPositionController">
      <joint_name>l_knee</joint_name><topic>/l_knee/cmd</topic>
      <p_gain>40</p_gain><i_gain>0.1</i_gain><d_gain>2.0</d_gain>
    </plugin>
    <plugin filename="gz-sim-joint-position-controller-system" name="gz::sim::systems::JointPositionController">
      <joint_name>r_knee</joint_name><topic>/r_knee/cmd</topic>
      <p_gain>40</p_gain><i_gain>0.1</i_gain><d_gain>2.0</d_gain>
    </plugin>
    <plugin name="ArduPilotPlugin" filename="ArduPilotPlugin">
      <fdm_addr>127.0.0.1</fdm_addr><fdm_port_in>9002</fdm_port_in>
      <connectionTimeoutMaxCount>5</connectionTimeoutMaxCount><lock_step>0</lock_step>
      <modelXYZToAirplaneXForwardZDown degrees="true">0 0 0 180 0 0</modelXYZToAirplaneXForwardZDown>
      <gazeboXYZToNED degrees="true">0 0 0 180 0 90</gazeboXYZToNED>
      <imuName>torso::imu_sensor</imuName>
      <control channel="0"><jointName>l_hip_pitch</jointName><type>COMMAND</type>
        <cmd_topic>/l_hip_pitch/cmd</cmd_topic><p_gain>15.0</p_gain>
        <servo_min>1000</servo_min><servo_max>2000</servo_max><multiplier>1.571</multiplier><offset>-0.5</offset>
      </control>
      <control channel="1"><jointName>r_hip_pitch</jointName><type>COMMAND</type>
        <cmd_topic>/r_hip_pitch/cmd</cmd_topic><p_gain>15.0</p_gain>
        <servo_min>1000</servo_min><servo_max>2000</servo_max><multiplier>1.571</multiplier><offset>-0.5</offset>
      </control>
      <control channel="2"><jointName>l_knee</jointName><type>COMMAND</type>
        <cmd_topic>/l_knee/cmd</cmd_topic><p_gain>15.0</p_gain>
        <servo_min>1000</servo_min><servo_max>2000</servo_max><multiplier>1.571</multiplier><offset>-0.5</offset>
      </control>
      <control channel="3"><jointName>r_knee</jointName><type>COMMAND</type>
        <cmd_topic>/r_knee/cmd</cmd_topic><p_gain>15.0</p_gain>
        <servo_min>1000</servo_min><servo_max>2000</servo_max><multiplier>1.571</multiplier><offset>-0.5</offset>
>>>>>>> Stashed changes
=======
      <parent>torso</parent><child>l_thigh</child>
      <pose>0 0.06 -0.025 0 0 0</pose>
      <axis><xyz>0 1 0</xyz>
        <limit><lower>-0.785</lower><upper>0.785</upper><effort>50</effort><velocity>5</velocity></limit>
        <dynamics><damping>8.0</damping><friction>1.0</friction></dynamics>
      </axis>
    </joint>
    <joint name="l_knee" type="revolute">
      <parent>l_thigh</parent><child>l_shin</child>
      <pose>0 0.06 -0.225 0 0 0</pose>
      <axis><xyz>0 1 0</xyz>
        <limit><lower>-0.1</lower><upper>1.571</upper><effort>50</effort><velocity>5</velocity></limit>
        <dynamics><damping>8.0</damping><friction>1.0</friction></dynamics>
      </axis>
    </joint>
    <joint name="l_ankle" type="fixed"><parent>l_shin</parent><child>l_foot</child></joint>
    <joint name="r_hip_pitch" type="revolute">
      <parent>torso</parent><child>r_thigh</child>
      <pose>0 -0.06 -0.025 0 0 0</pose>
      <axis><xyz>0 1 0</xyz>
        <limit><lower>-0.785</lower><upper>0.785</upper><effort>50</effort><velocity>5</velocity></limit>
        <dynamics><damping>8.0</damping><friction>1.0</friction></dynamics>
      </axis>
    </joint>
    <joint name="r_knee" type="revolute">
      <parent>r_thigh</parent><child>r_shin</child>
      <pose>0 -0.06 -0.225 0 0 0</pose>
      <axis><xyz>0 1 0</xyz>
        <limit><lower>-0.1</lower><upper>1.571</upper><effort>50</effort><velocity>5</velocity></limit>
        <dynamics><damping>8.0</damping><friction>1.0</friction></dynamics>
      </axis>
    </joint>
    <joint name="r_ankle" type="fixed"><parent>r_shin</parent><child>r_foot</child></joint>
    <plugin filename="gz-sim-joint-position-controller-system" name="gz::sim::systems::JointPositionController">
      <joint_name>l_hip_pitch</joint_name><topic>/l_hip_pitch/cmd</topic>
      <p_gain>40</p_gain><i_gain>0.1</i_gain><d_gain>2.0</d_gain>
    </plugin>
    <plugin filename="gz-sim-joint-position-controller-system" name="gz::sim::systems::JointPositionController">
      <joint_name>r_hip_pitch</joint_name><topic>/r_hip_pitch/cmd</topic>
      <p_gain>40</p_gain><i_gain>0.1</i_gain><d_gain>2.0</d_gain>
    </plugin>
    <plugin filename="gz-sim-joint-position-controller-system" name="gz::sim::systems::JointPositionController">
      <joint_name>l_knee</joint_name><topic>/l_knee/cmd</topic>
      <p_gain>40</p_gain><i_gain>0.1</i_gain><d_gain>2.0</d_gain>
    </plugin>
    <plugin filename="gz-sim-joint-position-controller-system" name="gz::sim::systems::JointPositionController">
      <joint_name>r_knee</joint_name><topic>/r_knee/cmd</topic>
      <p_gain>40</p_gain><i_gain>0.1</i_gain><d_gain>2.0</d_gain>
    </plugin>
    <plugin name="ArduPilotPlugin" filename="ArduPilotPlugin">
      <fdm_addr>127.0.0.1</fdm_addr><fdm_port_in>9002</fdm_port_in>
      <connectionTimeoutMaxCount>5</connectionTimeoutMaxCount><lock_step>0</lock_step>
      <modelXYZToAirplaneXForwardZDown degrees="true">0 0 0 180 0 0</modelXYZToAirplaneXForwardZDown>
      <gazeboXYZToNED degrees="true">0 0 0 180 0 90</gazeboXYZToNED>
      <imuName>torso::imu_sensor</imuName>
      <control channel="0"><jointName>l_hip_pitch</jointName><type>COMMAND</type>
        <cmd_topic>/l_hip_pitch/cmd</cmd_topic><p_gain>15.0</p_gain>
        <servo_min>1000</servo_min><servo_max>2000</servo_max><multiplier>1.571</multiplier><offset>-0.5</offset>
      </control>
      <control channel="1"><jointName>r_hip_pitch</jointName><type>COMMAND</type>
        <cmd_topic>/r_hip_pitch/cmd</cmd_topic><p_gain>15.0</p_gain>
        <servo_min>1000</servo_min><servo_max>2000</servo_max><multiplier>1.571</multiplier><offset>-0.5</offset>
      </control>
      <control channel="2"><jointName>l_knee</jointName><type>COMMAND</type>
        <cmd_topic>/l_knee/cmd</cmd_topic><p_gain>15.0</p_gain>
        <servo_min>1000</servo_min><servo_max>2000</servo_max><multiplier>1.571</multiplier><offset>-0.5</offset>
      </control>
      <control channel="3"><jointName>r_knee</jointName><type>COMMAND</type>
        <cmd_topic>/r_knee/cmd</cmd_topic><p_gain>15.0</p_gain>
        <servo_min>1000</servo_min><servo_max>2000</servo_max><multiplier>1.571</multiplier><offset>-0.5</offset>
>>>>>>> Stashed changes
      </control>
    </plugin>

    <plugin filename="gz-sim-joint-state-publisher-system"
            name="gz::sim::systems::JointStatePublisher">
    </plugin>
    <plugin filename="gz-sim-joint-position-controller-system" name="gz::sim::systems::JointPositionController"><joint_name>l_hip_pitch</joint_name><topic>/l_hip_pitch/cmd</topic><p_gain>8</p_gain><i_gain>0.01</i_gain><d_gain>0.1</d_gain></plugin>
    <plugin filename="gz-sim-joint-position-controller-system" name="gz::sim::systems::JointPositionController"><joint_name>r_hip_pitch</joint_name><topic>/r_hip_pitch/cmd</topic><p_gain>8</p_gain><i_gain>0.01</i_gain><d_gain>0.1</d_gain></plugin>
    <plugin filename="gz-sim-joint-position-controller-system" name="gz::sim::systems::JointPositionController"><joint_name>l_knee</joint_name><topic>/l_knee/cmd</topic><p_gain>8</p_gain><i_gain>0.01</i_gain><d_gain>0.1</d_gain></plugin>
    <plugin filename="gz-sim-joint-position-controller-system" name="gz::sim::systems::JointPositionController"><joint_name>r_knee</joint_name><topic>/r_knee/cmd</topic><p_gain>8</p_gain><i_gain>0.01</i_gain><d_gain>0.1</d_gain></plugin>
  </model>
</sdf>
